<?xml version="1.0" ?>
<!-- =================================================================================== -->
<!-- |    This document was autogenerated by xacro from dual_robot.xacro               | -->
<!-- |    EDITING THIS FILE BY HAND IS NOT RECOMMENDED                                 | -->
<!-- =================================================================================== -->
<robot name="dual_robot">
  <link name="world"/>
  <!-- <joint name="fixed" type="fixed"> 
        <parent link="world"/>
        <child link="base_link"/>
        <origin xyz="0 0 0" rpy="0.0 0.0 0.0" />
    </joint> -->
  <!-- word-link virtual  -->
  <!-- <link  name="world"/> -->
  <joint name="desk_base_virtual_joint" type="fixed">
    <origin rpy="0 0 0 " xyz="0 0 0.80"/>
    <parent link="world"/>
    <child link="desk_base_link"/>
    <axis xyz="0 0 0"/>
  </joint>
  <link name="desk_base_link">
    <inertial>
      <origin rpy="0 0 0" xyz="-0.063008 -0.00052857 -0.46249"/>
      <mass value="55.905"/>
      <inertia ixx="3.103" ixy="1.3699E-10" ixz="2.067E-07" iyy="5.8604" iyz="-4.3153E-05" izz="8.8128"/>
    </inertial>
    <visual>
      <origin rpy="0 0 0" xyz="0 0 0"/>
      <geometry>
        <mesh filename="../dual_description/meshes/desk/desk_base_link.STL"/>
      </geometry>
      <material name="">
        <color rgba="1 1 1 1"/>
      </material>
    </visual>
    <collision>
      <origin rpy="0 0 0" xyz="0 0 0"/>
      <geometry>
        <mesh filename="../dual_description/meshes/desk/desk_base_link.STL"/>
      </geometry>
    </collision>
  </link>
  <link name="desk_mount_link">
    <inertial>
      <origin rpy="0 0 0" xyz="7.6091E-06 3.8956E-17 -0.0075038"/>
      <mass value="5.9136"/>
      <inertia ixx="0.17815" ixy="-1.5368E-17" ixz="2.2481E-07" iyy="0.22281" iyz="-1.3218E-19" izz="0.40074"/>
    </inertial>
    <visual>
      <origin rpy="0 0 0" xyz="0 0 0"/>
      <geometry>
        <mesh filename="../dual_description/meshes/desk/desk_mount_link.STL"/>
      </geometry>
      <material name="">
        <color rgba="1 1 1 1"/>
      </material>
    </visual>
    <collision>
      <origin rpy="0 0 0" xyz="0 0 0"/>
      <geometry>
        <mesh filename="../dual_description/meshes/desk/desk_mount_link.STL"/>
      </geometry>
    </collision>
  </link>
  <joint name="desk_mount_joint" type="fixed">
    <origin rpy="0 0 0" xyz="-0.380101825806298 0 0.0140000000000009"/>
    <parent link="desk_base_link"/>
    <child link="desk_mount_link"/>
    <axis xyz="0 0 0"/>
  </joint>
  <!-- word-link virtual  -->
  <!-- <link  name="world"/> -->
  <joint name="body_base_virtual_joint" type="fixed">
    <origin rpy="0 0 0 " xyz="0 0 0"/>
    <parent link="desk_mount_link"/>
    <child link="body_base_link"/>
    <axis xyz="0 0 0"/>
  </joint>
  <link name="body_base_link">
    <inertial>
      <origin rpy="0 0 0" xyz="0.00584259577469448 -4.04386794715782E-08 0.558193747400135"/>
      <mass value="2.08668584314991"/>
      <inertia ixx="0.0512261321298791" ixy="5.92998368553023E-08" ixz="-0.000723201881816007" iyy="0.0380361473621072" iyz="-3.14601048029688E-09" izz="0.0177505726695456"/>
    </inertial>
    <visual>
      <origin rpy="0 0 0" xyz="0 0 0"/>
      <geometry>
        <mesh filename="../dual_description/meshes/body/body_base_link.STL"/>
      </geometry>
      <material name="">
        <color rgba="0.898039215686275 0.827450980392157 0.117647058823529 1"/>
      </material>
    </visual>
    <collision>
      <origin rpy="0 0 0" xyz="0 0 0"/>
      <geometry>
        <mesh filename="../dual_description/meshes/body/body_base_link.STL"/>
      </geometry>
    </collision>
  </link>
  <link name="base_right_virtual_link">
  </link>
  <joint name="base_right_virtual_joint" type="fixed">
    <origin rpy="3.14159265358979 0.785398163397448 1.5707963267949" xyz="0 -0.174748737341515 0.641109127034685"/>
    <parent link="body_base_link"/>
    <child link="base_right_virtual_link"/>
    <axis xyz="0 0 0"/>
  </joint>
  <link name="base_left_virtual_link">
  </link>
  <joint name="base_left_virtual_joint" type="fixed">
    <origin rpy="-2.35619449019234 0 0" xyz="0 0.1747487373415 0.6411091270347"/>
    <parent link="body_base_link"/>
    <child link="base_left_virtual_link"/>
    <axis xyz="0 0 0"/>
  </joint>
  <link name="base_top_link">
    <inertial>
      <origin rpy="0 0 0" xyz="0.108332956333131 0.000502097590396251 -0.00120945092499425"/>
      <mass value="1.25028431536434"/>
      <inertia ixx="0.0164242467597889" ixy="-2.83203220956064E-07" ixz="-0.000301478836533527" iyy="0.00761411158725398" iyz="-5.82682403225744E-07" izz="0.00935899938889483"/>
    </inertial>
    <visual>
      <origin rpy="0 0 0" xyz="0 0 0"/>
      <geometry>
        <mesh filename="../dual_description/meshes/body/base_top_link.STL"/>
      </geometry>
      <material name="">
        <color rgba="0.898039215686275 0.827450980392157 0.117647058823529 1"/>
      </material>
    </visual>
    <collision>
      <origin rpy="0 0 0" xyz="0 0 0"/>
      <geometry>
        <mesh filename="../dual_description/meshes/body/base_top_link.STL"/>
      </geometry>
    </collision>
  </link>
  <!-- change  top to base_link -->
  <joint name="base_top_joint" type="fixed">
    <origin rpy="0 0.25 0" xyz="0.0450000000000174 0 0.918859127034699"/>
    <parent link="body_base_link"/>
    <child link="base_top_link"/>
    <axis xyz="0 0 0"/>
  </joint>
  <link name="top_mid_virtual_link">
  </link>
  <joint name="top_mid_virtual_joint" type="fixed">
    <origin rpy="-1.5707963267949 0.349065850398898 0" xyz="0.0831335832259699 0 -0.0902711429138859"/>
    <parent link="base_top_link"/>
    <child link="top_mid_virtual_link"/>
    <axis xyz="0 0 0"/>
  </joint>
  <link name="top_camera_link">
    <inertial>
      <origin rpy="0 0 0" xyz="0.0191201663252327 3.1965938699802E-15 -0.0120428973987055"/>
      <mass value="0.00818486414704422"/>
      <inertia ixx="5.38039839342553E-06" ixy="9.70130285742726E-23" ixz="4.71160702476488E-07" iyy="2.08946621689711E-06" iyz="7.5952468703513E-22" izz="6.33794581580629E-06"/>
    </inertial>
    <visual>
      <origin rpy="0 0 0" xyz="0 0 0"/>
      <geometry>
        <mesh filename="../dual_description/meshes/body/top_camera_link.STL"/>
      </geometry>
      <material name="">
        <color rgba="1 1 1 1"/>
      </material>
    </visual>
    <collision>
      <origin rpy="0 0 0" xyz="0 0 0"/>
      <geometry>
        <mesh filename="../dual_description/meshes/body/top_camera_link.STL"/>
      </geometry>
    </collision>
  </link>
  <joint name="top_camera_joint" type="fixed">
    <origin rpy="-3.14159265358979 0.65 0" xyz="0.101149999999983 0 0.154750000000001"/>
    <parent link="base_top_link"/>
    <child link="top_camera_link"/>
    <axis xyz="0 0 0"/>
  </joint>
  <link name="top_camera_virtual_link">
  </link>
  <joint name="top_camera_virtual_joint" type="fixed">
    <origin rpy="3.14159265358979 0 0" xyz="0.0327999999999819 0 -0.0149999999999817"/>
    <parent link="top_camera_link"/>
    <child link="top_camera_virtual_link"/>
    <axis xyz="0 0 0"/>
  </joint>
  <material name="black">
    <color rgba="0.0 0.0 0.0 1.0"/>
  </material>
  <material name="blue">
    <color rgba="0.0 0.0 0.8 1.0"/>
  </material>
  <material name="green">
    <color rgba="0.0 0.8 0.0 1.0"/>
  </material>
  <material name="grey">
    <color rgba="0.2 0.2 0.2 1.0"/>
  </material>
  <material name="orange">
    <color rgba="1.0 0.4235294117647059 0.0392156862745098 1.0"/>
  </material>
  <material name="brown">
    <color rgba="0.8705882352941177 0.8117647058823529 0.7647058823529411 1.0"/>
  </material>
  <material name="red">
    <color rgba="0.8 0.0 0.0 1.0"/>
  </material>
  <material name="white">
    <color rgba="1.0 1.0 1.0 1.0"/>
  </material>
  <material name="Beige">
    <color rgba="1.0 0.784 0.5765 1.0"/>
  </material>
  <!--
    Base UR robot series xacro macro.

    NOTE: this is NOT a URDF. It cannot directly be loaded by consumers
    expecting a flattened '.urdf' file. See the top-level '.xacro' for that
    (but note: that .xacro must still be processed by the xacro command).

    For use in '.launch' files: use one of the 'load_urX.launch' convenience
    launch files.

    This file models the base kinematic chain of a UR robot, which then gets
    parameterised by various configuration files to convert it into a UR3(e),
    UR5(e), UR10(e), UR16e or UR20.

    NOTE: the default kinematic parameters (ie: link lengths, frame locations,
    offets, etc) do not correspond to any particular robot. They are defaults
    only. There WILL be non-zero offsets between the Forward Kinematics results
    in TF (ie: robot_state_publisher) and the values reported by the Teach
    Pendant.

    For accurate (and robot-specific) transforms, the 'kinematics_parameters_file'
    parameter MUST point to a .yaml file containing the appropriate values for
    the targetted robot.

    If using the UniversalRobots/Universal_Robots_ROS_Driver, follow the steps
    described in the readme of that repository to extract the kinematic
    calibration from the controller and generate the required .yaml file.

    Main author of the migration to yaml configs: Ludovic Delval.

    Contributors to previous versions (in no particular order):

     - Felix Messmer
     - Kelsey Hawkins
     - Wim Meeussen
     - Shaun Edwards
     - Nadia Hammoudeh Garcia
     - Dave Hershberger
     - G. vd. Hoorn
     - Philip Long
     - Dave Coleman
     - Miguel Prada
     - Mathias Luedtke
     - Marcel Schnirring
     - Felix von Drigalski
     - Felix Exner
     - Jimmy Da Silva
     - Ajit Krisshna N L
     - Muhammad Asif Rana
  -->
  <!--
    NOTE: the macro defined in this file is NOT part of the public API of this
          package. Users CANNOT rely on this file being available, or stored in
          this location. Nor can they rely on the existence of the macro.
  -->
  <transmission name="left_shoulder_pan_trans">
    <type>transmission_interface/SimpleTransmission</type>
    <joint name="left_shoulder_pan_joint">
      <hardwareInterface>hardware_interface/PositionJointInterface</hardwareInterface>
    </joint>
    <actuator name="left_shoulder_pan_motor">
      <mechanicalReduction>1</mechanicalReduction>
    </actuator>
  </transmission>
  <transmission name="left_shoulder_lift_trans">
    <type>transmission_interface/SimpleTransmission</type>
    <joint name="left_shoulder_lift_joint">
      <hardwareInterface>hardware_interface/PositionJointInterface</hardwareInterface>
    </joint>
    <actuator name="left_shoulder_lift_motor">
      <mechanicalReduction>1</mechanicalReduction>
    </actuator>
  </transmission>
  <transmission name="left_elbow_trans">
    <type>transmission_interface/SimpleTransmission</type>
    <joint name="left_elbow_joint">
      <hardwareInterface>hardware_interface/PositionJointInterface</hardwareInterface>
    </joint>
    <actuator name="left_elbow_motor">
      <mechanicalReduction>1</mechanicalReduction>
    </actuator>
  </transmission>
  <transmission name="left_wrist_1_trans">
    <type>transmission_interface/SimpleTransmission</type>
    <joint name="left_wrist_1_joint">
      <hardwareInterface>hardware_interface/PositionJointInterface</hardwareInterface>
    </joint>
    <actuator name="left_wrist_1_motor">
      <mechanicalReduction>1</mechanicalReduction>
    </actuator>
  </transmission>
  <transmission name="left_wrist_2_trans">
    <type>transmission_interface/SimpleTransmission</type>
    <joint name="left_wrist_2_joint">
      <hardwareInterface>hardware_interface/PositionJointInterface</hardwareInterface>
    </joint>
    <actuator name="left_wrist_2_motor">
      <mechanicalReduction>1</mechanicalReduction>
    </actuator>
  </transmission>
  <transmission name="left_wrist_3_trans">
    <type>transmission_interface/SimpleTransmission</type>
    <joint name="left_wrist_3_joint">
      <hardwareInterface>hardware_interface/PositionJointInterface</hardwareInterface>
    </joint>
    <actuator name="left_wrist_3_motor">
      <mechanicalReduction>1</mechanicalReduction>
    </actuator>
  </transmission>
  <!-- links: main serial chain -->
  <link name="left_base_link"/>
  <link name="left_base_link_inertia">
    <visual>
      <origin rpy="0 0 3.141592653589793" xyz="0 0 0"/>
      <geometry>
        <mesh filename="../dual_description/meshes/visual/base.dae"/>
      </geometry>
      <material name="LightGrey">
        <color rgba="0.7 0.7 0.7 1.0"/>
      </material>
    </visual>
    <collision>
      <origin rpy="0 0 3.141592653589793" xyz="0 0 0"/>
      <geometry>
        <mesh filename="../dual_description/meshes/collision/base.stl"/>
      </geometry>
    </collision>
    <inertial>
      <mass value="4.0"/>
      <origin rpy="0 0 0" xyz="0 0 0"/>
      <inertia ixx="0.00443333156" ixy="0.0" ixz="0.0" iyy="0.00443333156" iyz="0.0" izz="0.0072"/>
    </inertial>
  </link>
  <link name="left_shoulder_link">
    <visual>
      <origin rpy="0 0 3.141592653589793" xyz="0 0 0"/>
      <geometry>
        <mesh filename="../dual_description/meshes/visual/shoulder.dae"/>
      </geometry>
      <material name="LightGrey">
        <color rgba="0.7 0.7 0.7 1.0"/>
      </material>
    </visual>
    <collision>
      <origin rpy="0 0 3.141592653589793" xyz="0 0 0"/>
      <geometry>
        <mesh filename="../dual_description/meshes/collision/shoulder.stl"/>
      </geometry>
    </collision>
    <inertial>
      <mass value="3.7"/>
      <origin rpy="0 0 0" xyz="0 0 0"/>
      <inertia ixx="0.010267495893" ixy="0.0" ixz="0.0" iyy="0.010267495893" iyz="0.0" izz="0.00666"/>
    </inertial>
  </link>
  <link name="left_upper_arm_link">
    <visual>
      <origin rpy="1.5707963267948966 0 -1.5707963267948966" xyz="0 0 0.138"/>
      <geometry>
        <mesh filename="../dual_description/meshes/visual/upperarm.dae"/>
      </geometry>
      <material name="LightGrey">
        <color rgba="0.7 0.7 0.7 1.0"/>
      </material>
    </visual>
    <collision>
      <origin rpy="1.5707963267948966 0 -1.5707963267948966" xyz="0 0 0.138"/>
      <geometry>
        <mesh filename="../dual_description/meshes/collision/upperarm.stl"/>
      </geometry>
    </collision>
    <inertial>
      <mass value="8.393"/>
      <origin rpy="0 1.5707963267948966 0" xyz="-0.2125 0.0 0.138"/>
      <inertia ixx="0.1338857818623325" ixy="0.0" ixz="0.0" iyy="0.1338857818623325" iyz="0.0" izz="0.0151074"/>
    </inertial>
  </link>
  <link name="left_forearm_link">
    <visual>
      <origin rpy="1.5707963267948966 0 -1.5707963267948966" xyz="0 0 0.007"/>
      <geometry>
        <mesh filename="../dual_description/meshes/visual/forearm.dae"/>
      </geometry>
      <material name="LightGrey">
        <color rgba="0.7 0.7 0.7 1.0"/>
      </material>
    </visual>
    <collision>
      <origin rpy="1.5707963267948966 0 -1.5707963267948966" xyz="0 0 0.007"/>
      <geometry>
        <mesh filename="../dual_description/meshes/collision/forearm.stl"/>
      </geometry>
    </collision>
    <inertial>
      <mass value="2.275"/>
      <origin rpy="0 1.5707963267948966 0" xyz="-0.1961 0.0 0.007"/>
      <inertia ixx="0.031209355099586295" ixy="0.0" ixz="0.0" iyy="0.031209355099586295" iyz="0.0" izz="0.004095"/>
    </inertial>
  </link>
  <link name="left_wrist_1_link">
    <visual>
      <!-- TODO: Move this to a parameter -->
      <origin rpy="1.5707963267948966 0 0" xyz="0 0 -0.127"/>
      <geometry>
        <mesh filename="../dual_description/meshes/visual/wrist1.dae"/>
      </geometry>
      <material name="LightGrey">
        <color rgba="0.7 0.7 0.7 1.0"/>
      </material>
    </visual>
    <collision>
      <origin rpy="1.5707963267948966 0 0" xyz="0 0 -0.127"/>
      <geometry>
        <mesh filename="../dual_description/meshes/collision/wrist1.stl"/>
      </geometry>
    </collision>
    <inertial>
      <mass value="1.219"/>
      <origin rpy="0 0 0" xyz="0 0 0"/>
      <inertia ixx="0.0025598989760400002" ixy="0.0" ixz="0.0" iyy="0.0025598989760400002" iyz="0.0" izz="0.0021942"/>
    </inertial>
  </link>
  <link name="left_wrist_2_link">
    <visual>
      <origin rpy="0 0 0" xyz="0 0 -0.0997"/>
      <geometry>
        <mesh filename="../dual_description/meshes/visual/wrist2.dae"/>
      </geometry>
      <material name="LightGrey">
        <color rgba="0.7 0.7 0.7 1.0"/>
      </material>
    </visual>
    <collision>
      <origin rpy="0 0 0" xyz="0 0 -0.0997"/>
      <geometry>
        <mesh filename="../dual_description/meshes/collision/wrist2.stl"/>
      </geometry>
    </collision>
    <inertial>
      <mass value="1.219"/>
      <origin rpy="0 0 0" xyz="0 0 0"/>
      <inertia ixx="0.0025598989760400002" ixy="0.0" ixz="0.0" iyy="0.0025598989760400002" iyz="0.0" izz="0.0021942"/>
    </inertial>
  </link>
  <link name="left_wrist_3_link">
    <visual>
      <origin rpy="1.5707963267948966 0 0" xyz="0 0 -0.0989"/>
      <geometry>
        <mesh filename="../dual_description/meshes/visual/wrist3.dae"/>
      </geometry>
      <material name="LightGrey">
        <color rgba="0.7 0.7 0.7 1.0"/>
      </material>
    </visual>
    <collision>
      <origin rpy="1.5707963267948966 0 0" xyz="0 0 -0.0989"/>
      <geometry>
        <mesh filename="../dual_description/meshes/collision/wrist3.stl"/>
      </geometry>
    </collision>
    <inertial>
      <mass value="0.1879"/>
      <origin rpy="0 0 0" xyz="0.0 0.0 -0.0229"/>
      <inertia ixx="9.890410052167731e-05" ixy="0.0" ixz="0.0" iyy="9.890410052167731e-05" iyz="0.0" izz="0.0001321171875"/>
    </inertial>
  </link>
  <!-- joints: main serial chain -->
  <joint name="left_base_link-base_link_inertia" type="fixed">
    <parent link="left_base_link"/>
    <child link="left_base_link_inertia"/>
    <!-- 'base_link' is REP-103 aligned (so X+ forward), while the internal
           frames of the robot/controller have X+ pointing backwards.
           Use the joint between 'base_link' and 'base_link_inertia' (a dummy
           link/frame) to introduce the necessary rotation over Z (of pi rad).
      -->
    <origin rpy="0 0 3.141592653589793" xyz="0 0 0"/>
  </joint>
  <joint name="left_shoulder_pan_joint" type="revolute">
    <parent link="left_base_link_inertia"/>
    <child link="left_shoulder_link"/>
    <origin rpy="0 0 0" xyz="0 0 0.1625"/>
    <axis xyz="0 0 1"/>
    <limit effort="150.0" lower="-6.283185307179586" upper="6.283185307179586" velocity="3.141592653589793"/>
    <dynamics damping="0" friction="0"/>
  </joint>
  <joint name="left_shoulder_lift_joint" type="revolute">
    <parent link="left_shoulder_link"/>
    <child link="left_upper_arm_link"/>
    <origin rpy="1.570796327 0 0" xyz="0 0 0"/>
    <axis xyz="0 0 1"/>
    <limit effort="150.0" lower="-6.283185307179586" upper="6.283185307179586" velocity="3.141592653589793"/>
    <dynamics damping="0" friction="0"/>
  </joint>
  <joint name="left_elbow_joint" type="revolute">
    <parent link="left_upper_arm_link"/>
    <child link="left_forearm_link"/>
    <origin rpy="0 0 0" xyz="-0.425 0 0"/>
    <axis xyz="0 0 1"/>
    <limit effort="150.0" lower="-3.141592653589793" upper="3.141592653589793" velocity="3.141592653589793"/>
    <dynamics damping="0" friction="0"/>
  </joint>
  <joint name="left_wrist_1_joint" type="revolute">
    <parent link="left_forearm_link"/>
    <child link="left_wrist_1_link"/>
    <origin rpy="0 0 0" xyz="-0.3922 0 0.1333"/>
    <axis xyz="0 0 1"/>
    <limit effort="28.0" lower="-6.283185307179586" upper="6.283185307179586" velocity="3.141592653589793"/>
    <dynamics damping="0" friction="0"/>
  </joint>
  <joint name="left_wrist_2_joint" type="revolute">
    <parent link="left_wrist_1_link"/>
    <child link="left_wrist_2_link"/>
    <origin rpy="1.570796327 0 0" xyz="0 -0.0997 -2.044881182297852e-11"/>
    <axis xyz="0 0 1"/>
    <limit effort="28.0" lower="-6.283185307179586" upper="6.283185307179586" velocity="3.141592653589793"/>
    <dynamics damping="0" friction="0"/>
  </joint>
  <joint name="left_wrist_3_joint" type="revolute">
    <parent link="left_wrist_2_link"/>
    <child link="left_wrist_3_link"/>
    <origin rpy="1.570796326589793 3.141592653589793 3.141592653589793" xyz="0 0.0996 -2.042830148012698e-11"/>
    <axis xyz="0 0 1"/>
    <limit effort="28.0" lower="-6.283185307179586" upper="6.283185307179586" velocity="3.141592653589793"/>
    <dynamics damping="0" friction="0"/>
  </joint>
  <!-- ROS-Industrial 'base' frame: base_link to UR 'Base' Coordinates transform -->
  <link name="left_base"/>
  <joint name="left_base_link-base_fixed_joint" type="fixed">
    <!-- Note the rotation over Z of pi radians: as base_link is REP-103
           aligned (ie: has X+ forward, Y+ left and Z+ up), this is needed
           to correctly align 'base' with the 'Base' coordinate system of
           the UR controller.
      -->
    <origin rpy="0 0 3.141592653589793" xyz="0 0 0"/>
    <parent link="left_base_link"/>
    <child link="left_base"/>
  </joint>
  <!-- ROS-Industrial 'flange' frame: attachment point for EEF models -->
  <link name="left_flange"/>
  <joint name="left_wrist_3-flange" type="fixed">
    <parent link="left_wrist_3_link"/>
    <child link="left_flange"/>
    <origin rpy="0 -1.5707963267948966 -1.5707963267948966" xyz="0 0 0"/>
  </joint>
  <!-- ROS-Industrial 'tool0' frame: all-zeros tool frame -->
  <link name="left_tool0"/>
  <joint name="left_flange-tool0" type="fixed">
    <!-- default toolframe: X+ left, Y+ up, Z+ front -->
    <origin rpy="1.5707963267948966 0 1.5707963267948966" xyz="0 0 0"/>
    <parent link="left_flange"/>
    <child link="left_tool0"/>
  </joint>
  <joint name="left_fixed" type="fixed">
    <parent link="base_left_virtual_link"/>
    <child link="left_base_link"/>
    <origin rpy="0 0 3.141592653" xyz="0 0 0"/>
  </joint>
  <!--
    Base UR robot series xacro macro.

    NOTE: this is NOT a URDF. It cannot directly be loaded by consumers
    expecting a flattened '.urdf' file. See the top-level '.xacro' for that
    (but note: that .xacro must still be processed by the xacro command).

    For use in '.launch' files: use one of the 'load_urX.launch' convenience
    launch files.

    This file models the base kinematic chain of a UR robot, which then gets
    parameterised by various configuration files to convert it into a UR3(e),
    UR5(e), UR10(e), UR16e or UR20.

    NOTE: the default kinematic parameters (ie: link lengths, frame locations,
    offets, etc) do not correspond to any particular robot. They are defaults
    only. There WILL be non-zero offsets between the Forward Kinematics results
    in TF (ie: robot_state_publisher) and the values reported by the Teach
    Pendant.

    For accurate (and robot-specific) transforms, the 'kinematics_parameters_file'
    parameter MUST point to a .yaml file containing the appropriate values for
    the targetted robot.

    If using the UniversalRobots/Universal_Robots_ROS_Driver, follow the steps
    described in the readme of that repository to extract the kinematic
    calibration from the controller and generate the required .yaml file.

    Main author of the migration to yaml configs: Ludovic Delval.

    Contributors to previous versions (in no particular order):

     - Felix Messmer
     - Kelsey Hawkins
     - Wim Meeussen
     - Shaun Edwards
     - Nadia Hammoudeh Garcia
     - Dave Hershberger
     - G. vd. Hoorn
     - Philip Long
     - Dave Coleman
     - Miguel Prada
     - Mathias Luedtke
     - Marcel Schnirring
     - Felix von Drigalski
     - Felix Exner
     - Jimmy Da Silva
     - Ajit Krisshna N L
     - Muhammad Asif Rana
  -->
  <!--
    NOTE: the macro defined in this file is NOT part of the public API of this
          package. Users CANNOT rely on this file being available, or stored in
          this location. Nor can they rely on the existence of the macro.
  -->
  <transmission name="right_shoulder_pan_trans">
    <type>transmission_interface/SimpleTransmission</type>
    <joint name="right_shoulder_pan_joint">
      <hardwareInterface>hardware_interface/PositionJointInterface</hardwareInterface>
    </joint>
    <actuator name="right_shoulder_pan_motor">
      <mechanicalReduction>1</mechanicalReduction>
    </actuator>
  </transmission>
  <transmission name="right_shoulder_lift_trans">
    <type>transmission_interface/SimpleTransmission</type>
    <joint name="right_shoulder_lift_joint">
      <hardwareInterface>hardware_interface/PositionJointInterface</hardwareInterface>
    </joint>
    <actuator name="right_shoulder_lift_motor">
      <mechanicalReduction>1</mechanicalReduction>
    </actuator>
  </transmission>
  <transmission name="right_elbow_trans">
    <type>transmission_interface/SimpleTransmission</type>
    <joint name="right_elbow_joint">
      <hardwareInterface>hardware_interface/PositionJointInterface</hardwareInterface>
    </joint>
    <actuator name="right_elbow_motor">
      <mechanicalReduction>1</mechanicalReduction>
    </actuator>
  </transmission>
  <transmission name="right_wrist_1_trans">
    <type>transmission_interface/SimpleTransmission</type>
    <joint name="right_wrist_1_joint">
      <hardwareInterface>hardware_interface/PositionJointInterface</hardwareInterface>
    </joint>
    <actuator name="right_wrist_1_motor">
      <mechanicalReduction>1</mechanicalReduction>
    </actuator>
  </transmission>
  <transmission name="right_wrist_2_trans">
    <type>transmission_interface/SimpleTransmission</type>
    <joint name="right_wrist_2_joint">
      <hardwareInterface>hardware_interface/PositionJointInterface</hardwareInterface>
    </joint>
    <actuator name="right_wrist_2_motor">
      <mechanicalReduction>1</mechanicalReduction>
    </actuator>
  </transmission>
  <transmission name="right_wrist_3_trans">
    <type>transmission_interface/SimpleTransmission</type>
    <joint name="right_wrist_3_joint">
      <hardwareInterface>hardware_interface/PositionJointInterface</hardwareInterface>
    </joint>
    <actuator name="right_wrist_3_motor">
      <mechanicalReduction>1</mechanicalReduction>
    </actuator>
  </transmission>
  <!-- links: main serial chain -->
  <link name="right_base_link"/>
  <link name="right_base_link_inertia">
    <visual>
      <origin rpy="0 0 3.141592653589793" xyz="0 0 0"/>
      <geometry>
        <mesh filename="../dual_description/meshes/visual/base.dae"/>
      </geometry>
      <material name="LightGrey">
        <color rgba="0.7 0.7 0.7 1.0"/>
      </material>
    </visual>
    <collision>
      <origin rpy="0 0 3.141592653589793" xyz="0 0 0"/>
      <geometry>
        <mesh filename="../dual_description/meshes/collision/base.stl"/>
      </geometry>
    </collision>
    <inertial>
      <mass value="4.0"/>
      <origin rpy="0 0 0" xyz="0 0 0"/>
      <inertia ixx="0.00443333156" ixy="0.0" ixz="0.0" iyy="0.00443333156" iyz="0.0" izz="0.0072"/>
    </inertial>
  </link>
  <link name="right_shoulder_link">
    <visual>
      <origin rpy="0 0 3.141592653589793" xyz="0 0 0"/>
      <geometry>
        <mesh filename="../dual_description/meshes/visual/shoulder.dae"/>
      </geometry>
      <material name="LightGrey">
        <color rgba="0.7 0.7 0.7 1.0"/>
      </material>
    </visual>
    <collision>
      <origin rpy="0 0 3.141592653589793" xyz="0 0 0"/>
      <geometry>
        <mesh filename="../dual_description/meshes/collision/shoulder.stl"/>
      </geometry>
    </collision>
    <inertial>
      <mass value="3.7"/>
      <origin rpy="0 0 0" xyz="0 0 0"/>
      <inertia ixx="0.010267495893" ixy="0.0" ixz="0.0" iyy="0.010267495893" iyz="0.0" izz="0.00666"/>
    </inertial>
  </link>
  <link name="right_upper_arm_link">
    <visual>
      <origin rpy="1.5707963267948966 0 -1.5707963267948966" xyz="0 0 0.138"/>
      <geometry>
        <mesh filename="../dual_description/meshes/visual/upperarm.dae"/>
      </geometry>
      <material name="LightGrey">
        <color rgba="0.7 0.7 0.7 1.0"/>
      </material>
    </visual>
    <collision>
      <origin rpy="1.5707963267948966 0 -1.5707963267948966" xyz="0 0 0.138"/>
      <geometry>
        <mesh filename="../dual_description/meshes/collision/upperarm.stl"/>
      </geometry>
    </collision>
    <inertial>
      <mass value="8.393"/>
      <origin rpy="0 1.5707963267948966 0" xyz="-0.2125 0.0 0.138"/>
      <inertia ixx="0.1338857818623325" ixy="0.0" ixz="0.0" iyy="0.1338857818623325" iyz="0.0" izz="0.0151074"/>
    </inertial>
  </link>
  <link name="right_forearm_link">
    <visual>
      <origin rpy="1.5707963267948966 0 -1.5707963267948966" xyz="0 0 0.007"/>
      <geometry>
        <mesh filename="../dual_description/meshes/visual/forearm.dae"/>
      </geometry>
      <material name="LightGrey">
        <color rgba="0.7 0.7 0.7 1.0"/>
      </material>
    </visual>
    <collision>
      <origin rpy="1.5707963267948966 0 -1.5707963267948966" xyz="0 0 0.007"/>
      <geometry>
        <mesh filename="../dual_description/meshes/collision/forearm.stl"/>
      </geometry>
    </collision>
    <inertial>
      <mass value="2.275"/>
      <origin rpy="0 1.5707963267948966 0" xyz="-0.1961 0.0 0.007"/>
      <inertia ixx="0.031209355099586295" ixy="0.0" ixz="0.0" iyy="0.031209355099586295" iyz="0.0" izz="0.004095"/>
    </inertial>
  </link>
  <link name="right_wrist_1_link">
    <visual>
      <!-- TODO: Move this to a parameter -->
      <origin rpy="1.5707963267948966 0 0" xyz="0 0 -0.127"/>
      <geometry>
        <mesh filename="../dual_description/meshes/visual/wrist1.dae"/>
      </geometry>
      <material name="LightGrey">
        <color rgba="0.7 0.7 0.7 1.0"/>
      </material>
    </visual>
    <collision>
      <origin rpy="1.5707963267948966 0 0" xyz="0 0 -0.127"/>
      <geometry>
        <mesh filename="../dual_description/meshes/collision/wrist1.stl"/>
      </geometry>
    </collision>
    <inertial>
      <mass value="1.219"/>
      <origin rpy="0 0 0" xyz="0 0 0"/>
      <inertia ixx="0.0025598989760400002" ixy="0.0" ixz="0.0" iyy="0.0025598989760400002" iyz="0.0" izz="0.0021942"/>
    </inertial>
  </link>
  <link name="right_wrist_2_link">
    <visual>
      <origin rpy="0 0 0" xyz="0 0 -0.0997"/>
      <geometry>
        <mesh filename="../dual_description/meshes/visual/wrist2.dae"/>
      </geometry>
      <material name="LightGrey">
        <color rgba="0.7 0.7 0.7 1.0"/>
      </material>
    </visual>
    <collision>
      <origin rpy="0 0 0" xyz="0 0 -0.0997"/>
      <geometry>
        <mesh filename="../dual_description/meshes/collision/wrist2.stl"/>
      </geometry>
    </collision>
    <inertial>
      <mass value="1.219"/>
      <origin rpy="0 0 0" xyz="0 0 0"/>
      <inertia ixx="0.0025598989760400002" ixy="0.0" ixz="0.0" iyy="0.0025598989760400002" iyz="0.0" izz="0.0021942"/>
    </inertial>
  </link>
  <link name="right_wrist_3_link">
    <visual>
      <origin rpy="1.5707963267948966 0 0" xyz="0 0 -0.0989"/>
      <geometry>
        <mesh filename="../dual_description/meshes/visual/wrist3.dae"/>
      </geometry>
      <material name="LightGrey">
        <color rgba="0.7 0.7 0.7 1.0"/>
      </material>
    </visual>
    <collision>
      <origin rpy="1.5707963267948966 0 0" xyz="0 0 -0.0989"/>
      <geometry>
        <mesh filename="../dual_description/meshes/collision/wrist3.stl"/>
      </geometry>
    </collision>
    <inertial>
      <mass value="0.1879"/>
      <origin rpy="0 0 0" xyz="0.0 0.0 -0.0229"/>
      <inertia ixx="9.890410052167731e-05" ixy="0.0" ixz="0.0" iyy="9.890410052167731e-05" iyz="0.0" izz="0.0001321171875"/>
    </inertial>
  </link>
  <!-- joints: main serial chain -->
  <joint name="right_base_link-base_link_inertia" type="fixed">
    <parent link="right_base_link"/>
    <child link="right_base_link_inertia"/>
    <!-- 'base_link' is REP-103 aligned (so X+ forward), while the internal
           frames of the robot/controller have X+ pointing backwards.
           Use the joint between 'base_link' and 'base_link_inertia' (a dummy
           link/frame) to introduce the necessary rotation over Z (of pi rad).
      -->
    <origin rpy="0 0 3.141592653589793" xyz="0 0 0"/>
  </joint>
  <joint name="right_shoulder_pan_joint" type="revolute">
    <parent link="right_base_link_inertia"/>
    <child link="right_shoulder_link"/>
    <origin rpy="0 0 0" xyz="0 0 0.1625"/>
    <axis xyz="0 0 1"/>
    <limit effort="150.0" lower="-6.283185307179586" upper="6.283185307179586" velocity="3.141592653589793"/>
    <dynamics damping="0" friction="0"/>
  </joint>
  <joint name="right_shoulder_lift_joint" type="revolute">
    <parent link="right_shoulder_link"/>
    <child link="right_upper_arm_link"/>
    <origin rpy="1.570796327 0 0" xyz="0 0 0"/>
    <axis xyz="0 0 1"/>
    <limit effort="150.0" lower="-6.283185307179586" upper="6.283185307179586" velocity="3.141592653589793"/>
    <dynamics damping="0" friction="0"/>
  </joint>
  <joint name="right_elbow_joint" type="revolute">
    <parent link="right_upper_arm_link"/>
    <child link="right_forearm_link"/>
    <origin rpy="0 0 0" xyz="-0.425 0 0"/>
    <axis xyz="0 0 1"/>
    <limit effort="150.0" lower="-3.141592653589793" upper="3.141592653589793" velocity="3.141592653589793"/>
    <dynamics damping="0" friction="0"/>
  </joint>
  <joint name="right_wrist_1_joint" type="revolute">
    <parent link="right_forearm_link"/>
    <child link="right_wrist_1_link"/>
    <origin rpy="0 0 0" xyz="-0.3922 0 0.1333"/>
    <axis xyz="0 0 1"/>
    <limit effort="28.0" lower="-6.283185307179586" upper="6.283185307179586" velocity="3.141592653589793"/>
    <dynamics damping="0" friction="0"/>
  </joint>
  <joint name="right_wrist_2_joint" type="revolute">
    <parent link="right_wrist_1_link"/>
    <child link="right_wrist_2_link"/>
    <origin rpy="1.570796327 0 0" xyz="0 -0.0997 -2.044881182297852e-11"/>
    <axis xyz="0 0 1"/>
    <limit effort="28.0" lower="-6.283185307179586" upper="6.283185307179586" velocity="3.141592653589793"/>
    <dynamics damping="0" friction="0"/>
  </joint>
  <joint name="right_wrist_3_joint" type="revolute">
    <parent link="right_wrist_2_link"/>
    <child link="right_wrist_3_link"/>
    <origin rpy="1.570796326589793 3.141592653589793 3.141592653589793" xyz="0 0.0996 -2.042830148012698e-11"/>
    <axis xyz="0 0 1"/>
    <limit effort="28.0" lower="-6.283185307179586" upper="6.283185307179586" velocity="3.141592653589793"/>
    <dynamics damping="0" friction="0"/>
  </joint>
  <!-- ROS-Industrial 'base' frame: base_link to UR 'Base' Coordinates transform -->
  <link name="right_base"/>
  <joint name="right_base_link-base_fixed_joint" type="fixed">
    <!-- Note the rotation over Z of pi radians: as base_link is REP-103
           aligned (ie: has X+ forward, Y+ left and Z+ up), this is needed
           to correctly align 'base' with the 'Base' coordinate system of
           the UR controller.
      -->
    <origin rpy="0 0 3.141592653589793" xyz="0 0 0"/>
    <parent link="right_base_link"/>
    <child link="right_base"/>
  </joint>
  <!-- ROS-Industrial 'flange' frame: attachment point for EEF models -->
  <link name="right_flange"/>
  <joint name="right_wrist_3-flange" type="fixed">
    <parent link="right_wrist_3_link"/>
    <child link="right_flange"/>
    <origin rpy="0 -1.5707963267948966 -1.5707963267948966" xyz="0 0 0"/>
  </joint>
  <!-- ROS-Industrial 'tool0' frame: all-zeros tool frame -->
  <link name="right_tool0"/>
  <joint name="right_flange-tool0" type="fixed">
    <!-- default toolframe: X+ left, Y+ up, Z+ front -->
    <origin rpy="1.5707963267948966 0 1.5707963267948966" xyz="0 0 0"/>
    <parent link="right_flange"/>
    <child link="right_tool0"/>
  </joint>
  <joint name="right_fixed" type="fixed">
    <parent link="base_right_virtual_link"/>
    <child link="right_base_link"/>
    <origin rpy="0 0 1.57 " xyz="0 0 0"/>
  </joint>
  <!-- cameras -->
  <!-- Realsense Camera Primary and Secondary -->
  <!-- TOP D435i -->
  <!-- <link name="top_camera_realsense_depth_optical_frame" />
   
    <joint name="top_camera_realsense_depth_frame_joint" type="fixed" >
      <parent link="left_base" />
      <child link="top_camera_realsense_depth_optical_frame" />
      <origin xyz="-0.382 -0.233 -0.084" rpy="1.57 0.261 1.565" />
    </joint> -->
  <!--  -->
  <!-- <link name="top_camera_realsense_depth_optical_frame" />
   
    <joint name="top_camera_realsense_depth_frame_joint" type="fixed" >
      <parent link="left_base" />
      <child link="top_camera_realsense_depth_optical_frame" />
      <origin xyz="0.206 -0.147 -0.378" rpy=" 0 1.57 0" />
    </joint> -->
  <material name="aluminum">
    <color rgba="0.5 0.5 0.5 1"/>
  </material>
  <material name="plastic">
    <color rgba="0.1 0.1 0.1 1"/>
  </material>
  <!-- camera body, with origin at bottom screw mount -->
  <joint name="top_camera_realsense_joint" type="fixed">
    <origin rpy="0 0.22 0" xyz="0.015 0 0.03"/>
    <parent link="top_camera_virtual_link"/>
    <child link="top_camera_realsense_bottom_screw_frame"/>
  </joint>
  <link name="top_camera_realsense_bottom_screw_frame"/>
  <joint name="top_camera_realsense_link_joint" type="fixed">
    <origin rpy="0 0 0" xyz="0.010600000000000002 0.0175 0.0125"/>
    <parent link="top_camera_realsense_bottom_screw_frame"/>
    <child link="top_camera_realsense_link"/>
  </joint>
  <link name="top_camera_realsense_link">
    <visual>
      <!-- the mesh origin is at front plate in between the two infrared camera axes -->
      <origin rpy="1.5707963267948966 0 1.5707963267948966" xyz="0.0043 -0.0175 0"/>
      <geometry>
        <mesh filename="../realsense2_description/meshes/d435.dae"/>
      </geometry>
    </visual>
    <collision>
      <origin rpy="0 0 0" xyz="0 -0.0175 0"/>
      <geometry>
        <box size="0.02505 0.09 0.025"/>
      </geometry>
    </collision>
    <inertial>
      <!-- The following are not reliable values, and should not be used for modeling -->
      <mass value="0.072"/>
      <origin xyz="0 0 0"/>
      <inertia ixx="0.003881243" ixy="0.0" ixz="0.0" iyy="0.000498940" iyz="0.0" izz="0.003879257"/>
    </inertial>
  </link>
  <!-- camera depth joints and links -->
  <joint name="top_camera_realsense_depth_joint" type="fixed">
    <origin rpy="0 0 0" xyz="0 0 0"/>
    <parent link="top_camera_realsense_link"/>
    <child link="top_camera_realsense_depth_frame"/>
  </joint>
  <link name="top_camera_realsense_depth_frame"/>
  <joint name="top_camera_realsense_depth_optical_joint" type="fixed">
    <origin rpy="-1.5707963267948966 0 -1.5707963267948966" xyz="0 0 0"/>
    <parent link="top_camera_realsense_depth_frame"/>
    <child link="top_camera_realsense_depth_optical_frame"/>
  </joint>
  <link name="top_camera_realsense_depth_optical_frame"/>
  <!-- camera left IR joints and links -->
  <joint name="top_camera_realsense_infra1_joint" type="fixed">
    <origin rpy="0 0 0" xyz="0 0.0 0"/>
    <parent link="top_camera_realsense_link"/>
    <child link="top_camera_realsense_infra1_frame"/>
  </joint>
  <link name="top_camera_realsense_infra1_frame"/>
  <joint name="top_camera_realsense_infra1_optical_joint" type="fixed">
    <origin rpy="-1.5707963267948966 0 -1.5707963267948966" xyz="0 0 0"/>
    <parent link="top_camera_realsense_infra1_frame"/>
    <child link="top_camera_realsense_infra1_optical_frame"/>
  </joint>
  <link name="top_camera_realsense_infra1_optical_frame"/>
  <!-- camera right IR joints and links -->
  <joint name="top_camera_realsense_infra2_joint" type="fixed">
    <origin rpy="0 0 0" xyz="0 -0.05 0"/>
    <parent link="top_camera_realsense_link"/>
    <child link="top_camera_realsense_infra2_frame"/>
  </joint>
  <link name="top_camera_realsense_infra2_frame"/>
  <joint name="top_camera_realsense_infra2_optical_joint" type="fixed">
    <origin rpy="-1.5707963267948966 0 -1.5707963267948966" xyz="0 0 0"/>
    <parent link="top_camera_realsense_infra2_frame"/>
    <child link="top_camera_realsense_infra2_optical_frame"/>
  </joint>
  <link name="top_camera_realsense_infra2_optical_frame"/>
  <!-- camera color joints and links -->
  <joint name="top_camera_realsense_color_joint" type="fixed">
    <origin rpy="0 0 0" xyz="0 0.015 0"/>
    <parent link="top_camera_realsense_link"/>
    <child link="top_camera_realsense_color_frame"/>
  </joint>
  <link name="top_camera_realsense_color_frame"/>
  <joint name="top_camera_realsense_color_optical_joint" type="fixed">
    <origin rpy="-1.5707963267948966 0 -1.5707963267948966" xyz="0 0 0"/>
    <parent link="top_camera_realsense_color_frame"/>
    <child link="top_camera_realsense_color_optical_frame"/>
  </joint>
  <link name="top_camera_realsense_color_optical_frame"/>
  <link name="top_camera_realsense_accel_frame"/>
  <link name="top_camera_realsense_accel_optical_frame"/>
  <link name="top_camera_realsense_gyro_frame"/>
  <link name="top_camera_realsense_gyro_optical_frame"/>
  <joint name="top_camera_realsense_accel_joint" type="fixed">
    <origin rpy="0 0 0" xyz="-0.01174 -0.00552 0.0051"/>
    <parent link="top_camera_realsense_link"/>
    <child link="top_camera_realsense_accel_frame"/>
  </joint>
  <joint name="top_camera_realsense_accel_optical_joint" type="fixed">
    <origin rpy="-1.5707963267948966 0 -1.5707963267948966" xyz="0 0 0"/>
    <parent link="top_camera_realsense_accel_frame"/>
    <child link="top_camera_realsense_accel_optical_frame"/>
  </joint>
  <joint name="top_camera_realsense_gyro_joint" type="fixed">
    <origin rpy="0 0 0" xyz="-0.01174 -0.00552 0.0051"/>
    <parent link="top_camera_realsense_link"/>
    <child link="top_camera_realsense_gyro_frame"/>
  </joint>
  <joint name="top_camera_realsense_gyro_optical_joint" type="fixed">
    <origin rpy="-1.5707963267948966 0 -1.5707963267948966" xyz="0 0 0"/>
    <parent link="top_camera_realsense_gyro_frame"/>
    <child link="top_camera_realsense_gyro_optical_frame"/>
  </joint>
</robot>
